Workbook

Sheet 풀이
B2: 2-11 여러 시트 비교 — 풀이
B4: ① 나란히 놓기 | C4: 보기 → 새 창 → 보기 → 모두 정렬 → 세로. 각 창에서 다른 시트를 고릅니다.
B5: ② 같이 굴리기 | C5: 보기 → 나란히 보기 → 동시 스크롤. 두 창이 함께 움직입니다.
B6: ③ 수식으로 찾기 | C6: [수정기록] K5 에 비교 수식을 넣고 563행까지 끕니다. 같으면 TRUE, 다르면 FALSE.
B7: ④ FALSE 만 거르기 | C7: K열에 필터를 걸어 FALSE 만 고릅니다. 바뀐 줄만 남습니다.
B9: K열 수식 | C9: =AND(B5=원본기록!I5, C5=원본기록!J5, … I5=원본기록!P5) ← 여덟 칸을 한 번에
B10: L열 수식 | C10: =B5=원본기록!I5 ← 교안에 나온 한 칸짜리. 열마다 따로 볼 때 씁니다.
B11: 자리 주의 | C11: [원본기록] 은 왼쪽에 요약표가 붙어 있어 상세표가 I열부터입니다. [수정기록] 은 B열부터입니다. 그래서 B↔I 로 여덟 칸이 밀려 대응합니다.
B14: 답 — 563줄 중 7줄이 다릅니다
B15: 행 | C15: 바뀐 칸 | D15: 원본기록 | E15: 수정기록
B16: 37 | C16: 퇴근 | D16: (빈칸) | E16: 18:22:00
B17: 118 | C17: 퇴근 | D17: (빈칸) | E17: 21:40:00
C18: 야간근무 | D18: (빈칸) | E18: 야간근무
B19: 205 | C19: 구분 | D19: 평일(기본) | E19: 반차(수)
C20: 퇴근 | D20: 18:01:00 | E20: 13:02:00
B21: 291 | C21: 출근 | D21: 08:33 | E21: 09:12
C22: 지각 | D22: (빈칸) | E22: 지각
B23: 366 | C23: 구분 | D23: 휴일 | E23: 평일(토)
C24: 출근 | D24: - | E24: 09:05
C25: 퇴근 | D25: - | E25: 15:30
B26: 447 | C26: 퇴근 | D26: 18:18 | E26: 15:40:00
C27: 조퇴 | D27: (빈칸) | E27: 조퇴
B28: 522 | C28: 성명 | D28: 박인아 | E28: 나가자
B30: 눈으로는 못 찾습니다
B31: 13칸이 563줄 4,504칸 속에 흩어져 있습니다. K열 수식 + 필터면 몇 초입니다.

Sheet 원본기록
A2: 한마음 헤어샵 출퇴근 현황 (요약) | I2: 한마음 헤어샵 출퇴근 현황 (상세)
A4: 9 | B4: 초과근무(분) | C4: 시간외(분) | D4: 시간외(시간) | E4: 야간근무 | F4: 비고 | I4: 출근일자 | J4: 성명 | K4: 구분 | L4: 출근 | M4: 퇴근 | N4: 야간근무 | O4: 지각 | P4: 조퇴
A5: 이은나 | B5: 623 | C5: 934.5 | D5: 15.575 | E5: 4 | I5: 44075 | J5: 이은나 | K5: 평일(기본) | L5: 0.3625 | M5: 0.75833333
A6: 김진수 | B6: 631 | C6: 946.5 | D6: 15.775 | E6: 3 | I6: 44076 | J6: 이은나 | K6: 반차(수) | L6: 0.35902778 | M6: 0.52569444
A7: 김수로 | B7: 493 | C7: 739.5 | D7: 12.325 | E7: 1 | I7: 44077 | J7: 이은나 | K7: 평일(기본) | L7: 0.35972222 | M7: 0.77430556
A8: 박인아 | B8: 657 | C8: 985.5 | D8: 16.425 | E8: 1 | I8: 44078 | J8: 이은나 | K8: 평일(기본) | L8: 0.35763889 | M8: 0.75972222
A9: 장현수 | B9: 1579 | C9: 2368.5 | D9: 39.475 | E9: 6 | I9: 44079 | J9: 이은나 | K9: 평일(토) | L9: 0.34097222 | M9: 0.61944444
A10: 최준식 | B10: 34 | C10: 51 | D10: 0.85 | E10: 0 | I10: 44080 | J10: 이은나 | K10: 휴일 | L10: - | M10: -
A11: 나가자 | B11: 354 | C11: 531 | D11: 8.85 | E11: 3 | I11: 44081 | J11: 이은나 | K11: 평일(기본) | L11: 0.3625 | M11: 0.77430556
I12: 44082 | J12: 이은나 | K12: 평일(야간) | L12: 0.42847222 | M12: 0.86388889 | N12: 야간근무
A13: 10 | B13: 초과근무(분) | C13: 시간외(분) | D13: 시간외(시간) | E13: 야간근무 | F13: 비고 | I13: 44083 | J13: 이은나 | K13: 반차(수) | L13: 0.36041667 | M13: 0.53263889
A14: 이은나 | B14: 510 | C14: 765 | D14: 12.75 | E14: 5 | I14: 44084 | J14: 이은나 | K14: 평일(기본) | L14: 0.36180556 | M14: 0.75972222
A15: 김진수 | B15: 582 | C15: 873 | D15: 14.55 | E15: 4 | I15: 44085 | J15: 이은나 | K15: 평일(야간) | L15: 0.43055556 | M15: 0.84027778 | N15: 야간근무
A16: 김수로 | B16: 633 | C16: 949.5 | D16: 15.825 | E16: 2 | I16: 44086 | J16: 이은나 | K16: 평일(토) | L16: 0.34166667 | M16: 0.60902778
A17: 박인아 | B17: 594 | C17: 891 | D17: 14.85 | E17: 1 | I17: 44087 | J17: 이은나 | K17: 휴일 | L17: - | M17: -
A18: 장현수 | B18: 2010 | C18: 3015 | D18: 50.25 | E18: 7 | I18: 44088 | J18: 이은나 | K18: 조기(기본) | L18: 0.34236111 | M18: 0.73055556
A19: 최준식 | B19: 245 | C19: 367.5 | D19: 6.125 | E19: 2 | I19: 44089 | J19: 이은나 | K19: 조기(기본) | L19: 0.34027778 | M19: 0.7375
A20: 나가자 | B20: 539 | C20: 808.5 | D20: 13.475 | E20: 3 | I20: 44090 | J20: 이은나 | K20: 조기(수) | L20: 0.34166667 | M20: 0.57083333
I21: 44091 | J21: 이은나 | K21: 조기(기본) | L21: 0.34305556 | M21: 0.72916667
A22: 11 | B22: 초과근무(분) | C22: 시간외(분) | D22: 시간외(시간) | E22: 야간근무 | F22: 비고 | I22: 44092 | J22: 이은나 | K22: 조기(기본) | L22: 0.34236111 | M22: 0.73333333
A23: 이은나 | B23: 494 | C23: 741 | D23: 12.35 | E23: 3 | I23: 44093 | J23: 이은나 | K23: 반차(토) | L23: 0.33958333 | M23: 0.52430556
A24: 김진수 | B24: 700 | C24: 1050 | D24: 17.5 | E24: 5 | I24: 44094 | J24: 이은나 | K24: 휴일 | L24: - | M24: -
A25: 김수로 | B25: 620 | C25: 930 | D25: 15.5 | E25: 1 | I25: 44095 | J25: 이은나 | K25: 평일(기본) | L25: 0.35972222 | M25: 0.78958333
A26: 박인아 | B26: 768 | C26: 1152 | D26: 19.2 | E26: 1 | I26: 44096 | J26: 이은나 | K26: 평일(야간) | L26: 0.42708333 | M26: 0.83819444 | N26: 야간근무
A27: 장현수 | B27: 1950 | C27: 2925 | D27: 48.75 | E27: 8 | I27: 44097 | J27: 이은나 | K27: 반차(수) | L27: 0.35763889 | M27: 0.52361111
A28: 최준식 | B28: 428 | C28: 642 | D28: 10.7 | E28: 4 | I28: 44098 | J28: 이은나 | K28: 평일(기본) | L28: 0.36319444 | M28: 0.79513889
A29: 나가자 | B29: 486 | C29: 729 | D29: 12.15 | E29: 2 | I29: 44099 | J29: 이은나 | K29: 평일(야간) | L29: 0.42083333 | M29: 0.83194444 | N29: 야간근무 | P29: 조퇴
I30: 44100 | J30: 이은나 | K30: 평일(토) | L30: 0.34513889 | M30: 0.60555556
A31: 12 | B31: 초과근무(분) | C31: 시간외(분) | D31: 시간외(시간) | E31: 야간근무 | F31: 비고 | I31: 44101 | J31: 이은나 | K31: 휴일 | L31: - | M31: -
A32: 이은나 | B32: 0 | C32: 0 | D32: 0 | I32: 44075 | J32: 이은나 | K32: 평일(기본) | L32: 0.36388889 | M32: 0.76666667
A33: 김진수 | B33: 0 | C33: 0 | D33: 0 | I33: 44103 | J33: 이은나 | K33: 평일(야간) | L33: 0.42083333 | M33: 0.83611111 | N33: 야간근무
A34: 김수로 | B34: 0 | C34: 0 | D34: 0 | I34: 44104 | J34: 이은나 | K34: 휴일 | L34: - | M34: -
A35: 박인아 | B35: 0 | C35: 0 | D35: 0 | I35: 44075 | J35: 김진수 | K35: 평일(야간) | L35: 0.42222222 | M35: 0.88055556 | N35: 야간근무
A36: 장현수 | B36: 0 | C36: 0 | D36: 0 | I36: 44076 | J36: 김진수 | K36: 반차(수) | L36: 0.35763889 | M36: 0.53541667
A37: 최준식 | B37: 0 | C37: 0 | D37: 0 | I37: 44077 | J37: 김진수 | K37: 평일(기본) | L37: 0.36111111
A38: 나가자 | B38: 0 | C38: 0 | D38: 0 | I38: 44078 | J38: 김진수 | K38: 평일(야간) | L38: 0.42916667 | M38: 0.84097222 | N38: 야간근무
I39: 44079 | J39: 김진수 | K39: 평일(토) | L39: 0.34861111 | M39: 0.6
A40: 2021 | I40: 44080 | J40: 김진수 | K40: 휴일 | L40: - | M40: -
A41: 1 | B41: 초과근무(분) | C41: 시간외(분) | D41: 시간외(시간) | E41: 야간근무 | F41: 비고 | I41: 44081 | J41: 김진수 | K41: 평일(기본) | L41: 0.35972222 | M41: 0.77430556
A42: 이은나 | B42: 0 | C42: 0 | D42: 0 | I42: 44082 | J42: 김진수 | K42: 평일(야간) | L42: 0.43819444 | M42: 0.86388889 | N42: 야간근무 | O42: 지각
...

Sheet 수정기록
B2: 한마음 헤어샵 출퇴근 현황 (상세) - ver.2
B4: 출근일자 | C4: 성명 | D4: 구분 | E4: 출근 | F4: 퇴근 | G4: 야간근무 | H4: 지각 | I4: 조퇴 | K4: 원본과 같은가 | L4: 한 열만 볼 때 | M4: 다른 줄 수
B5: 44075 | C5: 이은나 | D5: 평일(기본) | E5: 0.3625 | F5: 0.75833333 | K5: =AND(B5=원본기록!I5,C5=원본기록!J5,D5=원본기록!K5,E5=원본기록!L5,F5=원본기록!M5,G5=원본기록!N5,H5=원본기록!O5,I5=원본기록!P5) | L5: =B5=원본기록!I5 | M5: =COUNTIF(K5:K563,FALSE)
B6: 44076 | C6: 이은나 | D6: 반차(수) | E6: 0.35902778 | F6: 0.52569444 | K6: =AND(B6=원본기록!I6,C6=원본기록!J6,D6=원본기록!K6,E6=원본기록!L6,F6=원본기록!M6,G6=원본기록!N6,H6=원본기록!O6,I6=원본기록!P6) | L6: =B6=원본기록!I6
B7: 44077 | C7: 이은나 | D7: 평일(기본) | E7: 0.35972222 | F7: 0.77430556 | K7: =AND(B7=원본기록!I7,C7=원본기록!J7,D7=원본기록!K7,E7=원본기록!L7,F7=원본기록!M7,G7=원본기록!N7,H7=원본기록!O7,I7=원본기록!P7) | L7: =B7=원본기록!I7
B8: 44078 | C8: 이은나 | D8: 평일(기본) | E8: 0.35763889 | F8: 0.75972222 | K8: =AND(B8=원본기록!I8,C8=원본기록!J8,D8=원본기록!K8,E8=원본기록!L8,F8=원본기록!M8,G8=원본기록!N8,H8=원본기록!O8,I8=원본기록!P8) | L8: =B8=원본기록!I8
B9: 44079 | C9: 이은나 | D9: 평일(토) | E9: 0.34097222 | F9: 0.61944444 | K9: =AND(B9=원본기록!I9,C9=원본기록!J9,D9=원본기록!K9,E9=원본기록!L9,F9=원본기록!M9,G9=원본기록!N9,H9=원본기록!O9,I9=원본기록!P9) | L9: =B9=원본기록!I9
B10: 44080 | C10: 이은나 | D10: 휴일 | E10: - | F10: - | K10: =AND(B10=원본기록!I10,C10=원본기록!J10,D10=원본기록!K10,E10=원본기록!L10,F10=원본기록!M10,G10=원본기록!N10,H10=원본기록!O10,I10=원본기록!P10) | L10: =B10=원본기록!I10
B11: 44081 | C11: 이은나 | D11: 평일(기본) | E11: 0.3625 | F11: 0.77430556 | K11: =AND(B11=원본기록!I11,C11=원본기록!J11,D11=원본기록!K11,E11=원본기록!L11,F11=원본기록!M11,G11=원본기록!N11,H11=원본기록!O11,I11=원본기록!P11) | L11: =B11=원본기록!I11
B12: 44082 | C12: 이은나 | D12: 평일(야간) | E12: 0.42847222 | F12: 0.86388889 | G12: 야간근무 | K12: =AND(B12=원본기록!I12,C12=원본기록!J12,D12=원본기록!K12,E12=원본기록!L12,F12=원본기록!M12,G12=원본기록!N12,H12=원본기록!O12,I12=원본기록!P12) | L12: =B12=원본기록!I12
B13: 44083 | C13: 이은나 | D13: 반차(수) | E13: 0.36041667 | F13: 0.53263889 | K13: =AND(B13=원본기록!I13,C13=원본기록!J13,D13=원본기록!K13,E13=원본기록!L13,F13=원본기록!M13,G13=원본기록!N13,H13=원본기록!O13,I13=원본기록!P13) | L13: =B13=원본기록!I13
B14: 44084 | C14: 이은나 | D14: 평일(기본) | E14: 0.36180556 | F14: 0.75972222 | K14: =AND(B14=원본기록!I14,C14=원본기록!J14,D14=원본기록!K14,E14=원본기록!L14,F14=원본기록!M14,G14=원본기록!N14,H14=원본기록!O14,I14=원본기록!P14) | L14: =B14=원본기록!I14
B15: 44085 | C15: 이은나 | D15: 평일(야간) | E15: 0.43055556 | F15: 0.84027778 | G15: 야간근무 | K15: =AND(B15=원본기록!I15,C15=원본기록!J15,D15=원본기록!K15,E15=원본기록!L15,F15=원본기록!M15,G15=원본기록!N15,H15=원본기록!O15,I15=원본기록!P15) | L15: =B15=원본기록!I15
B16: 44086 | C16: 이은나 | D16: 평일(토) | E16: 0.34166667 | F16: 0.60902778 | K16: =AND(B16=원본기록!I16,C16=원본기록!J16,D16=원본기록!K16,E16=원본기록!L16,F16=원본기록!M16,G16=원본기록!N16,H16=원본기록!O16,I16=원본기록!P16) | L16: =B16=원본기록!I16
B17: 44087 | C17: 이은나 | D17: 휴일 | E17: - | F17: - | K17: =AND(B17=원본기록!I17,C17=원본기록!J17,D17=원본기록!K17,E17=원본기록!L17,F17=원본기록!M17,G17=원본기록!N17,H17=원본기록!O17,I17=원본기록!P17) | L17: =B17=원본기록!I17
B18: 44088 | C18: 이은나 | D18: 조기(기본) | E18: 0.34236111 | F18: 0.73055556 | K18: =AND(B18=원본기록!I18,C18=원본기록!J18,D18=원본기록!K18,E18=원본기록!L18,F18=원본기록!M18,G18=원본기록!N18,H18=원본기록!O18,I18=원본기록!P18) | L18: =B18=원본기록!I18
B19: 44089 | C19: 이은나 | D19: 조기(기본) | E19: 0.34027778 | F19: 0.7375 | K19: =AND(B19=원본기록!I19,C19=원본기록!J19,D19=원본기록!K19,E19=원본기록!L19,F19=원본기록!M19,G19=원본기록!N19,H19=원본기록!O19,I19=원본기록!P19) | L19: =B19=원본기록!I19
B20: 44090 | C20: 이은나 | D20: 조기(수) | E20: 0.34166667 | F20: 0.57083333 | K20: =AND(B20=원본기록!I20,C20=원본기록!J20,D20=원본기록!K20,E20=원본기록!L20,F20=원본기록!M20,G20=원본기록!N20,H20=원본기록!O20,I20=원본기록!P20) | L20: =B20=원본기록!I20
B21: 44091 | C21: 이은나 | D21: 조기(기본) | E21: 0.34305556 | F21: 0.72916667 | K21: =AND(B21=원본기록!I21,C21=원본기록!J21,D21=원본기록!K21,E21=원본기록!L21,F21=원본기록!M21,G21=원본기록!N21,H21=원본기록!O21,I21=원본기록!P21) | L21: =B21=원본기록!I21
B22: 44092 | C22: 이은나 | D22: 조기(기본) | E22: 0.34236111 | F22: 0.73333333 | K22: =AND(B22=원본기록!I22,C22=원본기록!J22,D22=원본기록!K22,E22=원본기록!L22,F22=원본기록!M22,G22=원본기록!N22,H22=원본기록!O22,I22=원본기록!P22) | L22: =B22=원본기록!I22
B23: 44093 | C23: 이은나 | D23: 반차(토) | E23: 0.33958333 | F23: 0.52430556 | K23: =AND(B23=원본기록!I23,C23=원본기록!J23,D23=원본기록!K23,E23=원본기록!L23,F23=원본기록!M23,G23=원본기록!N23,H23=원본기록!O23,I23=원본기록!P23) | L23: =B23=원본기록!I23
B24: 44094 | C24: 이은나 | D24: 휴일 | E24: - | F24: - | K24: =AND(B24=원본기록!I24,C24=원본기록!J24,D24=원본기록!K24,E24=원본기록!L24,F24=원본기록!M24,G24=원본기록!N24,H24=원본기록!O24,I24=원본기록!P24) | L24: =B24=원본기록!I24
B25: 44095 | C25: 이은나 | D25: 평일(기본) | E25: 0.35972222 | F25: 0.78958333 | K25: =AND(B25=원본기록!I25,C25=원본기록!J25,D25=원본기록!K25,E25=원본기록!L25,F25=원본기록!M25,G25=원본기록!N25,H25=원본기록!O25,I25=원본기록!P25) | L25: =B25=원본기록!I25
B26: 44096 | C26: 이은나 | D26: 평일(야간) | E26: 0.42708333 | F26: 0.83819444 | G26: 야간근무 | K26: =AND(B26=원본기록!I26,C26=원본기록!J26,D26=원본기록!K26,E26=원본기록!L26,F26=원본기록!M26,G26=원본기록!N26,H26=원본기록!O26,I26=원본기록!P26) | L26: =B26=원본기록!I26
B27: 44097 | C27: 이은나 | D27: 반차(수) | E27: 0.35763889 | F27: 0.52361111 | K27: =AND(B27=원본기록!I27,C27=원본기록!J27,D27=원본기록!K27,E27=원본기록!L27,F27=원본기록!M27,G27=원본기록!N27,H27=원본기록!O27,I27=원본기록!P27) | L27: =B27=원본기록!I27
B28: 44098 | C28: 이은나 | D28: 평일(기본) | E28: 0.36319444 | F28: 0.79513889 | K28: =AND(B28=원본기록!I28,C28=원본기록!J28,D28=원본기록!K28,E28=원본기록!L28,F28=원본기록!M28,G28=원본기록!N28,H28=원본기록!O28,I28=원본기록!P28) | L28: =B28=원본기록!I28
B29: 44099 | C29: 이은나 | D29: 평일(야간) | E29: 0.42083333 | F29: 0.83194444 | G29: 야간근무 | I29: 조퇴 | K29: =AND(B29=원본기록!I29,C29=원본기록!J29,D29=원본기록!K29,E29=원본기록!L29,F29=원본기록!M29,G29=원본기록!N29,H29=원본기록!O29,I29=원본기록!P29) | L29: =B29=원본기록!I29
B30: 44100 | C30: 이은나 | D30: 평일(토) | E30: 0.34513889 | F30: 0.60555556 | K30: =AND(B30=원본기록!I30,C30=원본기록!J30,D30=원본기록!K30,E30=원본기록!L30,F30=원본기록!M30,G30=원본기록!N30,H30=원본기록!O30,I30=원본기록!P30) | L30: =B30=원본기록!I30
B31: 44101 | C31: 이은나 | D31: 휴일 | E31: - | F31: - | K31: =AND(B31=원본기록!I31,C31=원본기록!J31,D31=원본기록!K31,E31=원본기록!L31,F31=원본기록!M31,G31=원본기록!N31,H31=원본기록!O31,I31=원본기록!P31) | L31: =B31=원본기록!I31
B32: 44075 | C32: 이은나 | D32: 평일(기본) | E32: 0.36388889 | F32: 0.76666667 | K32: =AND(B32=원본기록!I32,C32=원본기록!J32,D32=원본기록!K32,E32=원본기록!L32,F32=원본기록!M32,G32=원본기록!N32,H32=원본기록!O32,I32=원본기록!P32) | L32: =B32=원본기록!I32
B33: 44103 | C33: 이은나 | D33: 평일(야간) | E33: 0.42083333 | F33: 0.83611111 | G33: 야간근무 | K33: =AND(B33=원본기록!I33,C33=원본기록!J33,D33=원본기록!K33,E33=원본기록!L33,F33=원본기록!M33,G33=원본기록!N33,H33=원본기록!O33,I33=원본기록!P33) | L33: =B33=원본기록!I33
B34: 44104 | C34: 이은나 | D34: 휴일 | E34: - | F34: - | K34: =AND(B34=원본기록!I34,C34=원본기록!J34,D34=원본기록!K34,E34=원본기록!L34,F34=원본기록!M34,G34=원본기록!N34,H34=원본기록!O34,I34=원본기록!P34) | L34: =B34=원본기록!I34
B35: 44075 | C35: 김진수 | D35: 평일(야간) | E35: 0.42222222 | F35: 0.88055556 | G35: 야간근무 | K35: =AND(B35=원본기록!I35,C35=원본기록!J35,D35=원본기록!K35,E35=원본기록!L35,F35=원본기록!M35,G35=원본기록!N35,H35=원본기록!O35,I35=원본기록!P35) | L35: =B35=원본기록!I35
B36: 44076 | C36: 김진수 | D36: 반차(수) | E36: 0.35763889 | F36: 0.53541667 | K36: =AND(B36=원본기록!I36,C36=원본기록!J36,D36=원본기록!K36,E36=원본기록!L36,F36=원본기록!M36,G36=원본기록!N36,H36=원본기록!O36,I36=원본기록!P36) | L36: =B36=원본기록!I36
B37: 44077 | C37: 김진수 | D37: 평일(기본) | E37: 0.36111111 | F37: 0.76527778 | K37: =AND(B37=원본기록!I37,C37=원본기록!J37,D37=원본기록!K37,E37=원본기록!L37,F37=원본기록!M37,G37=원본기록!N37,H37=원본기록!O37,I37=원본기록!P37) | L37: =B37=원본기록!I37
B38: 44078 | C38: 김진수 | D38: 평일(야간) | E38: 0.42916667 | F38: 0.84097222 | G38: 야간근무 | K38: =AND(B38=원본기록!I38,C38=원본기록!J38,D38=원본기록!K38,E38=원본기록!L38,F38=원본기록!M38,G38=원본기록!N38,H38=원본기록!O38,I38=원본기록!P38) | L38: =B38=원본기록!I38
B39: 44079 | C39: 김진수 | D39: 평일(토) | E39: 0.34861111 | F39: 0.6 | K39: =AND(B39=원본기록!I39,C39=원본기록!J39,D39=원본기록!K39,E39=원본기록!L39,F39=원본기록!M39,G39=원본기록!N39,H39=원본기록!O39,I39=원본기록!P39) | L39: =B39=원본기록!I39
B40: 44080 | C40: 김진수 | D40: 휴일 | E40: - | F40: - | K40: =AND(B40=원본기록!I40,C40=원본기록!J40,D40=원본기록!K40,E40=원본기록!L40,F40=원본기록!M40,G40=원본기록!N40,H40=원본기록!O40,I40=원본기록!P40) | L40: =B40=원본기록!I40
B41: 44081 | C41: 김진수 | D41: 평일(기본) | E41: 0.35972222 | F41: 0.77430556 | K41: =AND(B41=원본기록!I41,C41=원본기록!J41,D41=원본기록!K41,E41=원본기록!L41,F41=원본기록!M41,G41=원본기록!N41,H41=원본기록!O41,I41=원본기록!P41) | L41: =B41=원본기록!I41
B42: 44082 | C42: 김진수 | D42: 평일(야간) | E42: 0.43819444 | F42: 0.86388889 | G42: 야간근무 | H42: 지각 | K42: =AND(B42=원본기록!I42,C42=원본기록!J42,D42=원본기록!K42,E42=원본기록!L42,F42=원본기록!M42,G42=원본기록!N42,H42=원본기록!O42,I42=원본기록!P42) | L42: =B42=원본기록!I42
...
